Workbook
Name St_NotRun: Lists!$A$5
Name St_Passed: Lists!$A$6
Name St_Failed: Lists!$A$7
Name St_Blocked: Lists!$A$8
Name St_Skipped: Lists!$A$9
Name Sev_1: Lists!$F$5
Name Sev_2: Lists!$F$6
Name IDPrefix: Lists!$N$5

Sheet Instructions
C2: QA TEST CASE WORKBOOK
C3: Test cases, beautifully organized.
C4: A little project to document test cases and bugs, built for job interviews and personal projects. Write a test, run it, record the result, and the dashboard keeps score. No macros, nothing to install.
C7: Quick start
B8: 1 | C8: Open Test Cases | D8: Rows with an SMP- ID are samples. Read them to see the level of detail, then edit or delete them.
B9: 2 | C9: Add a test case | D9: Go to the first empty row. Type the next ID shown in cell E3 (for example TC-001), then give it a title.
B10: 3 | C10: Describe it | D10: Click a cell in Module, Test Type or Priority and use the small arrow to choose. Then add Preconditions, Test Data, Steps and Expected Result.
B11: 4 | C11: Run it | D11: Follow the steps, write what happened in Actual Result and choose a Status. Add Tester, Environment and Date (Ctrl+; or Cmd+; enters today).
B12: 5 | C12: Report a failure | D12: Set Status to Failed, choose a Severity and describe the problem. Put your bug tracker link or ID in Notes.
B13: 6 | C13: Check the Dashboard | D13: Totals, pass rate, progress and results by module update on their own.
C15: The columns at a glance
C16: Describe | D16: ID, Title, Module, Test Type, Priority, Preconditions, Test Data, Test Steps, Expected Result and an optional Scenario (Given / When / Then).
C17: Run | D17: Status, Actual Result, Severity, Environment, Tester and Execution Date.
C18: Track | D18: Notes for links and remarks. The Check column flags missing or duplicate information. Hover over any header for details.
C20: Statuses
B21: ● | C21: Not Run | D21: Not executed yet.
B22: ● | C22: Passed | D22: Actual result matched the expected result.
B23: ● | C23: Failed | D23: Actual result differs from the expected result (a defect).
B24: ● | C24: Blocked | D24: Could not run because of an outside problem (environment down, blocking defect, missing data).
B25: ● | C25: Skipped | D25: Intentionally not run in this cycle.
C26: Priority vs. Severity | D26: Priority is how important it is to run (and fix) a test first. Severity is how serious the impact is when it fails.
C28: How the numbers work
C29: Pass rate | D29: Passed ÷ (Passed + Failed). Blocked, Skipped and Not Run are left out.
C30: Progress | D30: Share of tests whose status is anything other than Not Run. An empty status counts as Not Run.
C31: Highlighting | D31: Failed rows glow red and Blocked rows orange. Critical severity is red, High is orange. Sample IDs are blue.
C33: Make it yours
C34: Dropdown values | D34: Edit them on the Lists sheet. Type in an empty blue cell to add a value; overwrite one to rename it.
C35: Statuses | D35: Rename the five statuses if you like, but keep their order: the Dashboard counts them by position.
C36: More than 500 rows | D36: Drag the bottom-right corner of the table down, then copy the Check formula (last column) into the new rows.
C37: Start fresh | D37: Select the rows with SMP- IDs, right-click, Delete, Table Rows. The Dashboard resets to your own data.
C39: About the sample data
C40: Source | D40: 45 test cases from a private testing project on the Luma demo store, plus one extra Microsoft Edge test (SMP-046). Results (38 Passed, 8 Failed) are the original run. Where the original sheets disagreed, the row's Notes explain the choice.
C41: Scenario column | D41: The original Given / When / Then scenarios are kept in the Scenario column, with spelling cleaned. It is optional for your own tests.
C42: Left blank on purpose | D42: Priority, Severity, Environment, Tester and Execution Date were not recorded in the original work, so they are empty rather than invented.

Sheet Dashboard
B1: Dashboard
B2: Everything here updates automatically from the Test Cases sheet.
B4: TOTAL | C4: =UPPER(St_Passed) -> PASSED | D4: =UPPER(St_Failed) -> FAILED | E4: =UPPER(St_Blocked) -> BLOCKED | F4: =UPPER(St_Skipped) -> SKIPPED | G4: =UPPER(St_NotRun) -> NOT RUN | H4: PASS RATE | I4: PROGRESS
B5: =COUNTIF('Test Cases'!$B:$B,"?*")-1 -> 46 | C5: =COUNTIFS('Test Cases'!$B:$B,"?*",'Test Cases'!$F:$F,St_Passed) -> 38 | D5: =COUNTIFS('Test Cases'!$B:$B,"?*",'Test Cases'!$F:$F,St_Failed) -> 8 | E5: =COUNTIFS('Test Cases'!$B:$B,"?*",'Test Cases'!$F:$F,St_Blocked) -> 0 | F5: =COUNTIFS('Test Cases'!$B:$B,"?*",'Test Cases'!$F:$F,St_Skipped) -> 0 | G5: =B5-SUM(C5:F5) -> 0 | H5: =IF(C5+D5=0,"n/a",C5/(C5+D5)) -> 0.82608696 | I5: =IF(B5=0,"n/a",(B5-G5)/B5) -> 1
B6: test cases | C6: =IF($B$5=0,"",C5/$B$5) -> 0.82608696 | D6: =IF($B$5=0,"",D5/$B$5) -> 0.17391304 | E6: =IF($B$5=0,"",E5/$B$5) -> 0 | F6: =IF($B$5=0,"",F5/$B$5) -> 0 | G6: =IF($B$5=0,"",G5/$B$5) -> 0 | H6: Passed ÷ (Passed + Failed) | I6: Tests with a status ÷ total
B8: Status breakdown
B9: Status | C9: Count | D9: Share
B10: =St_Passed -> Passed | C10: =C5 -> 38 | D10: =IF($B$5=0,0,C10/$B$5) -> 0.82608696
B11: =St_Failed -> Failed | C11: =D5 -> 8 | D11: =IF($B$5=0,0,C11/$B$5) -> 0.17391304
B12: =St_Blocked -> Blocked | C12: =E5 -> 0 | D12: =IF($B$5=0,0,C12/$B$5) -> 0
B13: =St_Skipped -> Skipped | C13: =F5 -> 0 | D13: =IF($B$5=0,0,C13/$B$5) -> 0
B14: =St_NotRun -> Not Run | C14: =G5 -> 0 | D14: =IF($B$5=0,0,C14/$B$5) -> 0
B16: Failed tests by severity
B17: Severity | C17: Failed | D17: Share
B18: =IF(Lists!F5="","",Lists!F5) -> Critical | C18: =IF($B18="","",COUNTIFS('Test Cases'!$B:$B,"?*",'Test Cases'!$G:$G,$B18,'Test Cases'!$F:$F,St_Failed)) -> 0 | D18: =IF($B18="","",IF($D$5=0,0,C18/$D$5)) -> 0
B19: =IF(Lists!F6="","",Lists!F6) -> High | C19: =IF($B19="","",COUNTIFS('Test Cases'!$B:$B,"?*",'Test Cases'!$G:$G,$B19,'Test Cases'!$F:$F,St_Failed)) -> 0 | D19: =IF($B19="","",IF($D$5=0,0,C19/$D$5)) -> 0
B20: =IF(Lists!F7="","",Lists!F7) -> Medium | C20: =IF($B20="","",COUNTIFS('Test Cases'!$B:$B,"?*",'Test Cases'!$G:$G,$B20,'Test Cases'!$F:$F,St_Failed)) -> 0 | D20: =IF($B20="","",IF($D$5=0,0,C20/$D$5)) -> 0
B21: =IF(Lists!F8="","",Lists!F8) -> Low | C21: =IF($B21="","",COUNTIFS('Test Cases'!$B:$B,"?*",'Test Cases'!$G:$G,$B21,'Test Cases'!$F:$F,St_Failed)) -> 0 | D21: =IF($B21="","",IF($D$5=0,0,C21/$D$5)) -> 0
B22: Not set | C22: =COUNTIFS('Test Cases'!$B:$B,"?*",'Test Cases'!$G:$G,"",'Test Cases'!$F:$F,St_Failed) -> 8 | D22: =IF($D$5=0,0,C22/$D$5) -> 1
B24: Results by module
B25: Feature / Module | C25: Total | D25: =St_Passed -> Passed | E25: =St_Failed -> Failed | F25: =St_Blocked -> Blocked | G25: =St_Skipped -> Skipped | H25: =St_NotRun -> Not Run | I25: Pass rate
B26: =IF(Lists!L5="","",Lists!L5) -> Cross-Browser Compatibility | C26: =IF($B26="","",COUNTIFS('Test Cases'!$B:$B,"?*",'Test Cases'!$C:$C,$B26)) -> 4 | D26: =IF($B26="","",COUNTIFS('Test Cases'!$B:$B,"?*",'Test Cases'!$C:$C,$B26,'Test Cases'!$F:$F,St_Passed)) -> 4 | E26: =IF($B26="","",COUNTIFS('Test Cases'!$B:$B,"?*",'Test Cases'!$C:$C,$B26,'Test Cases'!$F:$F,St_Failed)) -> 0 | F26: =IF($B26="","",COUNTIFS('Test Cases'!$B:$B,"?*",'Test Cases'!$C:$C,$B26,'Test Cases'!$F:$F,St_Blocked)) -> 0 | G26: =IF($B26="","",COUNTIFS('Test Cases'!$B:$B,"?*",'Test Cases'!$C:$C,$B26,'Test Cases'!$F:$F,St_Skipped)) -> 0 | H26: =IF($B26="","",C26-SUM(D26:G26)) -> 0 | I26: =IF($B26="","",IF(D26+E26=0,"n/a",D26/(D26+E26))) -> 1
B27: =IF(Lists!L6="","",Lists!L6) -> Product Search | C27: =IF($B27="","",COUNTIFS('Test Cases'!$B:$B,"?*",'Test Cases'!$C:$C,$B27)) -> 5 | D27: =IF($B27="","",COUNTIFS('Test Cases'!$B:$B,"?*",'Test Cases'!$C:$C,$B27,'Test Cases'!$F:$F,St_Passed)) -> 2 | E27: =IF($B27="","",COUNTIFS('Test Cases'!$B:$B,"?*",'Test Cases'!$C:$C,$B27,'Test Cases'!$F:$F,St_Failed)) -> 3 | F27: =IF($B27="","",COUNTIFS('Test Cases'!$B:$B,"?*",'Test Cases'!$C:$C,$B27,'Test Cases'!$F:$F,St_Blocked)) -> 0 | G27: =IF($B27="","",COUNTIFS('Test Cases'!$B:$B,"?*",'Test Cases'!$C:$C,$B27,'Test Cases'!$F:$F,St_Skipped)) -> 0 | H27: =IF($B27="","",C27-SUM(D27:G27)) -> 0 | I27: =IF($B27="","",IF(D27+E27=0,"n/a",D27/(D27+E27))) -> 0.4
B28: =IF(Lists!L7="","",Lists!L7) -> Account Creation | C28: =IF($B28="","",COUNTIFS('Test Cases'!$B:$B,"?*",'Test Cases'!$C:$C,$B28)) -> 7 | D28: =IF($B28="","",COUNTIFS('Test Cases'!$B:$B,"?*",'Test Cases'!$C:$C,$B28,'Test Cases'!$F:$F,St_Passed)) -> 6 | E28: =IF($B28="","",COUNTIFS('Test Cases'!$B:$B,"?*",'Test Cases'!$C:$C,$B28,'Test Cases'!$F:$F,St_Failed)) -> 1 | F28: =IF($B28="","",COUNTIFS('Test Cases'!$B:$B,"?*",'Test Cases'!$C:$C,$B28,'Test Cases'!$F:$F,St_Blocked)) -> 0 | G28: =IF($B28="","",COUNTIFS('Test Cases'!$B:$B,"?*",'Test Cases'!$C:$C,$B28,'Test Cases'!$F:$F,St_Skipped)) -> 0 | H28: =IF($B28="","",C28-SUM(D28:G28)) -> 0 | I28: =IF($B28="","",IF(D28+E28=0,"n/a",D28/(D28+E28))) -> 0.85714286
B29: =IF(Lists!L8="","",Lists!L8) -> Add to Cart | C29: =IF($B29="","",COUNTIFS('Test Cases'!$B:$B,"?*",'Test Cases'!$C:$C,$B29)) -> 17 | D29: =IF($B29="","",COUNTIFS('Test Cases'!$B:$B,"?*",'Test Cases'!$C:$C,$B29,'Test Cases'!$F:$F,St_Passed)) -> 16 | E29: =IF($B29="","",COUNTIFS('Test Cases'!$B:$B,"?*",'Test Cases'!$C:$C,$B29,'Test Cases'!$F:$F,St_Failed)) -> 1 | F29: =IF($B29="","",COUNTIFS('Test Cases'!$B:$B,"?*",'Test Cases'!$C:$C,$B29,'Test Cases'!$F:$F,St_Blocked)) -> 0 | G29: =IF($B29="","",COUNTIFS('Test Cases'!$B:$B,"?*",'Test Cases'!$C:$C,$B29,'Test Cases'!$F:$F,St_Skipped)) -> 0 | H29: =IF($B29="","",C29-SUM(D29:G29)) -> 0 | I29: =IF($B29="","",IF(D29+E29=0,"n/a",D29/(D29+E29))) -> 0.94117647
B30: =IF(Lists!L9="","",Lists!L9) -> Ordering | C30: =IF($B30="","",COUNTIFS('Test Cases'!$B:$B,"?*",'Test Cases'!$C:$C,$B30)) -> 13 | D30: =IF($B30="","",COUNTIFS('Test Cases'!$B:$B,"?*",'Test Cases'!$C:$C,$B30,'Test Cases'!$F:$F,St_Passed)) -> 10 | E30: =IF($B30="","",COUNTIFS('Test Cases'!$B:$B,"?*",'Test Cases'!$C:$C,$B30,'Test Cases'!$F:$F,St_Failed)) -> 3 | F30: =IF($B30="","",COUNTIFS('Test Cases'!$B:$B,"?*",'Test Cases'!$C:$C,$B30,'Test Cases'!$F:$F,St_Blocked)) -> 0 | G30: =IF($B30="","",COUNTIFS('Test Cases'!$B:$B,"?*",'Test Cases'!$C:$C,$B30,'Test Cases'!$F:$F,St_Skipped)) -> 0 | H30: =IF($B30="","",C30-SUM(D30:G30)) -> 0 | I30: =IF($B30="","",IF(D30+E30=0,"n/a",D30/(D30+E30))) -> 0.76923077
B31: =IF(Lists!L10="","",Lists!L10) | C31: =IF($B31="","",COUNTIFS('Test Cases'!$B:$B,"?*",'Test Cases'!$C:$C,$B31)) | D31: =IF($B31="","",COUNTIFS('Test Cases'!$B:$B,"?*",'Test Cases'!$C:$C,$B31,'Test Cases'!$F:$F,St_Passed)) | E31: =IF($B31="","",COUNTIFS('Test Cases'!$B:$B,"?*",'Test Cases'!$C:$C,$B31,'Test Cases'!$F:$F,St_Failed)) | F31: =IF($B31="","",COUNTIFS('Test Cases'!$B:$B,"?*",'Test Cases'!$C:$C,$B31,'Test Cases'!$F:$F,St_Blocked)) | G31: =IF($B31="","",COUNTIFS('Test Cases'!$B:$B,"?*",'Test Cases'!$C:$C,$B31,'Test Cases'!$F:$F,St_Skipped)) | H31: =IF($B31="","",C31-SUM(D31:G31)) | I31: =IF($B31="","",IF(D31+E31=0,"n/a",D31/(D31+E31)))
B32: =IF(Lists!L11="","",Lists!L11) | C32: =IF($B32="","",COUNTIFS('Test Cases'!$B:$B,"?*",'Test Cases'!$C:$C,$B32)) | D32: =IF($B32="","",COUNTIFS('Test Cases'!$B:$B,"?*",'Test Cases'!$C:$C,$B32,'Test Cases'!$F:$F,St_Passed)) | E32: =IF($B32="","",COUNTIFS('Test Cases'!$B:$B,"?*",'Test Cases'!$C:$C,$B32,'Test Cases'!$F:$F,St_Failed)) | F32: =IF($B32="","",COUNTIFS('Test Cases'!$B:$B,"?*",'Test Cases'!$C:$C,$B32,'Test Cases'!$F:$F,St_Blocked)) | G32: =IF($B32="","",COUNTIFS('Test Cases'!$B:$B,"?*",'Test Cases'!$C:$C,$B32,'Test Cases'!$F:$F,St_Skipped)) | H32: =IF($B32="","",C32-SUM(D32:G32)) | I32: =IF($B32="","",IF(D32+E32=0,"n/a",D32/(D32+E32)))
B33: =IF(Lists!L12="","",Lists!L12) | C33: =IF($B33="","",COUNTIFS('Test Cases'!$B:$B,"?*",'Test Cases'!$C:$C,$B33)) | D33: =IF($B33="","",COUNTIFS('Test Cases'!$B:$B,"?*",'Test Cases'!$C:$C,$B33,'Test Cases'!$F:$F,St_Passed)) | E33: =IF($B33="","",COUNTIFS('Test Cases'!$B:$B,"?*",'Test Cases'!$C:$C,$B33,'Test Cases'!$F:$F,St_Failed)) | F33: =IF($B33="","",COUNTIFS('Test Cases'!$B:$B,"?*",'Test Cases'!$C:$C,$B33,'Test Cases'!$F:$F,St_Blocked)) | G33: =IF($B33="","",COUNTIFS('Test Cases'!$B:$B,"?*",'Test Cases'!$C:$C,$B33,'Test Cases'!$F:$F,St_Skipped)) | H33: =IF($B33="","",C33-SUM(D33:G33)) | I33: =IF($B33="","",IF(D33+E33=0,"n/a",D33/(D33+E33)))
B34: =IF(Lists!L13="","",Lists!L13) | C34: =IF($B34="","",COUNTIFS('Test Cases'!$B:$B,"?*",'Test Cases'!$C:$C,$B34)) | D34: =IF($B34="","",COUNTIFS('Test Cases'!$B:$B,"?*",'Test Cases'!$C:$C,$B34,'Test Cases'!$F:$F,St_Passed)) | E34: =IF($B34="","",COUNTIFS('Test Cases'!$B:$B,"?*",'Test Cases'!$C:$C,$B34,'Test Cases'!$F:$F,St_Failed)) | F34: =IF($B34="","",COUNTIFS('Test Cases'!$B:$B,"?*",'Test Cases'!$C:$C,$B34,'Test Cases'!$F:$F,St_Blocked)) | G34: =IF($B34="","",COUNTIFS('Test Cases'!$B:$B,"?*",'Test Cases'!$C:$C,$B34,'Test Cases'!$F:$F,St_Skipped)) | H34: =IF($B34="","",C34-SUM(D34:G34)) | I34: =IF($B34="","",IF(D34+E34=0,"n/a",D34/(D34+E34)))
B35: =IF(Lists!L14="","",Lists!L14) | C35: =IF($B35="","",COUNTIFS('Test Cases'!$B:$B,"?*",'Test Cases'!$C:$C,$B35)) | D35: =IF($B35="","",COUNTIFS('Test Cases'!$B:$B,"?*",'Test Cases'!$C:$C,$B35,'Test Cases'!$F:$F,St_Passed)) | E35: =IF($B35="","",COUNTIFS('Test Cases'!$B:$B,"?*",'Test Cases'!$C:$C,$B35,'Test Cases'!$F:$F,St_Failed)) | F35: =IF($B35="","",COUNTIFS('Test Cases'!$B:$B,"?*",'Test Cases'!$C:$C,$B35,'Test Cases'!$F:$F,St_Blocked)) | G35: =IF($B35="","",COUNTIFS('Test Cases'!$B:$B,"?*",'Test Cases'!$C:$C,$B35,'Test Cases'!$F:$F,St_Skipped)) | H35: =IF($B35="","",C35-SUM(D35:G35)) | I35: =IF($B35="","",IF(D35+E35=0,"n/a",D35/(D35+E35)))
B36: =IF(Lists!L15="","",Lists!L15) | C36: =IF($B36="","",COUNTIFS('Test Cases'!$B:$B,"?*",'Test Cases'!$C:$C,$B36)) | D36: =IF($B36="","",COUNTIFS('Test Cases'!$B:$B,"?*",'Test Cases'!$C:$C,$B36,'Test Cases'!$F:$F,St_Passed)) | E36: =IF($B36="","",COUNTIFS('Test Cases'!$B:$B,"?*",'Test Cases'!$C:$C,$B36,'Test Cases'!$F:$F,St_Failed)) | F36: =IF($B36="","",COUNTIFS('Test Cases'!$B:$B,"?*",'Test Cases'!$C:$C,$B36,'Test Cases'!$F:$F,St_Blocked)) | G36: =IF($B36="","",COUNTIFS('Test Cases'!$B:$B,"?*",'Test Cases'!$C:$C,$B36,'Test Cases'!$F:$F,St_Skipped)) | H36: =IF($B36="","",C36-SUM(D36:G36)) | I36: =IF($B36="","",IF(D36+E36=0,"n/a",D36/(D36+E36)))
B37: =IF(Lists!L16="","",Lists!L16) | C37: =IF($B37="","",COUNTIFS('Test Cases'!$B:$B,"?*",'Test Cases'!$C:$C,$B37)) | D37: =IF($B37="","",COUNTIFS('Test Cases'!$B:$B,"?*",'Test Cases'!$C:$C,$B37,'Test Cases'!$F:$F,St_Passed)) | E37: =IF($B37="","",COUNTIFS('Test Cases'!$B:$B,"?*",'Test Cases'!$C:$C,$B37,'Test Cases'!$F:$F,St_Failed)) | F37: =IF($B37="","",COUNTIFS('Test Cases'!$B:$B,"?*",'Test Cases'!$C:$C,$B37,'Test Cases'!$F:$F,St_Blocked)) | G37: =IF($B37="","",COUNTIFS('Test Cases'!$B:$B,"?*",'Test Cases'!$C:$C,$B37,'Test Cases'!$F:$F,St_Skipped)) | H37: =IF($B37="","",C37-SUM(D37:G37)) | I37: =IF($B37="","",IF(D37+E37=0,"n/a",D37/(D37+E37)))
B38: Other / no module | C38: =B5-SUM(C26:C37) -> 0 | D38: =C5-SUM(D26:D37) -> 0 | E38: =D5-SUM(E26:E37) -> 0 | F38: =E5-SUM(F26:F37) -> 0 | G38: =F5-SUM(G26:G37) -> 0 | H38: =C38-SUM(D38:G38) -> 0 | I38: =IF(D38+E38=0,"n/a",D38/(D38+E38)) -> n/a
B39: Total | C39: =SUM(C26:C38) -> 46 | D39: =SUM(D26:D38) -> 38 | E39: =SUM(E26:E38) -> 8 | F39: =SUM(F26:F38) -> 0 | G39: =SUM(G26:G38) -> 0 | H39: =SUM(H26:H38) -> 0 | I39: =IF(D39+E39=0,"n/a",D39/(D39+E39)) -> 0.82608696
B41: Data quality
B42: Incomplete or flagged test cases | E42: =COUNTIF('Test Cases'!$R:$R,"?*")-COUNTIF('Test Cases'!$R:$R,"OK")-1 -> 0 | F42: See the Check column on Test Cases.
B44: How it is calculated: Total = rows with a title. Pass rate = Passed ÷ (Passed + Failed). Progress = share of tests whose status is anything other than Not Run. Not Run = Total minus the other four statuses, so an empty status counts as Not Run.

Sheet Test Cases
A1: Test Cases
A2: Rows with an SMP- ID are samples from a private testing project on the Luma demo store. Edit or delete them and add your own below. Click a Status, Priority, Severity, Type, Module or Environment cell and use the arrow to choose.
D3: Next ID | E3: =IDPrefix&"-"&TEXT(COUNTIF($A:$A,IDPrefix&"-*")+1,"000") -> TC-001 | F3: type it in the ID column of your new row
A4: Test Case ID | B4: Test Case Title | C4: Feature / Module | D4: Test Type | E4: Priority | F4: Status | G4: Severity | H4: Preconditions | I4: Test Data | J4: Test Steps | K4: Expected Result | L4: Actual Result | M4: Environment | N4: Tester | O4: Execution Date | P4: Notes | Q4: Scenario (Given / When / Then) | R4: Check
A5: SMP-001 | B5: Website compatibility with Safari | C5: Cross-Browser Compatibility | D5: Compatibility | F5: Passed | H5: Computer/laptop with the Safari browser installed. | I5: URL: https://magento.softwaretestingboard.com/ | J5: 1. Open Safari. 2. Go to the Luma website. 3. Scroll through the site. 4. Open a random product. | K5: The website is compatible with the browser: it is fully functional and the layout is not broken. | Q5: Given that you have a computer/laptop that has a Safari Browser When you access Luma's website on the Safari Browser And scroll through the website And click on a product you desire Then the website should be compatible with your browser, meaning it should be fully functional and the layout shouldn't be broken | R5: =IF(AND(A5="",B5=""),"",IF(A5="","Missing ID",IF(COUNTIF($A:$A,A5)>1,"Duplicate ID",IF(B5="","Missing title",IF(C5="","Missing module",IF(J5="","Missing steps",IF(K5="","Missing expected result",IF(AND(F5=St_Failed,L5=""),"Add actual result","OK")))))))) -> OK
A6: SMP-002 | B6: Website compatibility with Google Chrome | C6: Cross-Browser Compatibility | D6: Compatibility | F6: Passed | H6: Computer/laptop with the Google Chrome browser installed. | I6: URL: https://magento.softwaretestingboard.com/ | J6: 1. Open Google Chrome. 2. Go to the Luma website. 3. Scroll through the site. 4. Open a random product. | K6: The website is compatible with the browser: it is fully functional and the layout is not broken. | Q6: Given that your laptop/computer has a Google Chrome browser When you access Luma's website on your Chrome And scroll through the website And click on a product you desire Then the website should be compatible with your browser, meaning it should be fully functional and the layout shouldn't be broken | R6: =IF(AND(A6="",B6=""),"",IF(A6="","Missing ID",IF(COUNTIF($A:$A,A6)>1,"Duplicate ID",IF(B6="","Missing title",IF(C6="","Missing module",IF(J6="","Missing steps",IF(K6="","Missing expected result",IF(AND(F6=St_Failed,L6=""),"Add actual result","OK")))))))) -> OK
A7: SMP-003 | B7: Website compatibility with Firefox | C7: Cross-Browser Compatibility | D7: Compatibility | F7: Passed | H7: Computer/laptop with the Firefox browser installed. | I7: URL: https://magento.softwaretestingboard.com/ | J7: 1. Open Firefox. 2. Go to the Luma website. 3. Scroll through the site. 4. Open a random product. | K7: The website is compatible with the browser: it is fully functional and the layout is not broken. | P7: The original test-case sheet listed Internet Explorer here (with Microsoft Edge noted); the original run sheet executed Firefox. This workbook follows the run sheet. | Q7: Given that you have a computer/laptop with the Firefox browser When you access Luma's website on Firefox And scroll through the website And click on a product you desire Then the website should be compatible with your browser, meaning it should be fully functional and the layout shouldn't be broken | R7: =IF(AND(A7="",B7=""),"",IF(A7="","Missing ID",IF(COUNTIF($A:$A,A7)>1,"Duplicate ID",IF(B7="","Missing title",IF(C7="","Missing module",IF(J7="","Missing steps",IF(K7="","Missing expected result",IF(AND(F7=St_Failed,L7=""),"Add actual result","OK")))))))) -> OK
A8: SMP-004 | B8: Search by keyword | C8: Product Search | D8: Functional | F8: Failed | H8: User is on the Luma home page. | I8: Keyword: "Jacket" | J8: 1. Click the search bar ("Search entire store here"). 2. Type a keyword for the desired product (see Test Data). 3. Press Enter or click the magnifying-glass icon. 4. Review the products in the results. | K8: The results only contain products that match the keyword. | L8: Products that do not contain the keyword appear in the search results. | Q8: Given that you are at Luma's home page When you click on the Search Bar that says "Search entire store here" And type a keyword of the desired product And click "Enter" or click on the magnifying glass icon to search Then the results should ONLY have products that contain the keyword | R8: =IF(AND(A8="",B8=""),"",IF(A8="","Missing ID",IF(COUNTIF($A:$A,A8)>1,"Duplicate ID",IF(B8="","Missing title",IF(C8="","Missing module",IF(J8="","Missing steps",IF(K8="","Missing expected result",IF(AND(F8=St_Failed,L8=""),"Add actual result","OK")))))))) -> OK
A9: SMP-005 | B9: Search by exact product title | C9: Product Search | D9: Functional | F9: Failed | H9: User is on the Luma home page. | I9: Product title: "Lucia Cross-Fit Bra" | J9: 1. Click the search bar. 2. Type the exact title of a product (see Test Data). 3. Press Enter or click the magnifying-glass icon. 4. Review the products in the results. | K9: The searched product appears first, followed by similar products with similar words in their titles. No unrelated products appear. | L9: The searched product and similar products appear, but unrelated random products also appear at the end of the results. | P9: The original run sheet used "Fusion Backpack" as the product title. | Q9: Given that you are at Luma's home page When you click on the Search Bar that says "Search entire store here" And you type the exact title of the desired product And click "Enter" or click on the magnifying glass icon to search Then the desired product should be the first one that appears And other similar products to the one you searched for should appear | R9: =IF(AND(A9="",B9=""),"",IF(A9="","Missing ID",IF(COUNTIF($A:$A,A9)>1,"Duplicate ID",IF(B9="","Missing title",IF(C9="","Missing module",IF(J9="","Missing steps",IF(K9="","Missing expected result",IF(AND(F9=St_Failed,L9=""),"Add actual result","OK")))))))) -> OK
A10: SMP-006 | B10: Search for a product that does not exist | C10: Product Search | D10: Negative | F10: Failed | H10: User is on the Luma home page. | I10: Search text: "Iphone 13 pro max" | J10: 1. Click the search bar. 2. Type the title of a product that does not exist in the store (see Test Data). 3. Run the search. | K10: No products are shown and the message "Your search returned no results" is displayed. | L10: Products unrelated to the search appear in the results. | P10: The original run sheet used "Samsung s22 ultra" as the search text. | Q10: Given that you are at Luma's home page When you click on the Search Bar that says "Search entire store here" And you type the exact title of a product that doesn't exist in the store And click "Enter" or click on the magnifying glass icon to search Then the site should display an error message "Your search returned no results" | R10: =IF(AND(A10="",B10=""),"",IF(A10="","Missing ID",IF(COUNTIF($A:$A,A10)>1,"Duplicate ID",IF(B10="","Missing title",IF(C10="","Missing module",IF(J10="","Missing steps",IF(K10="","Missing expected result",IF(AND(F10=St_Failed,L10=""),"Add actual result","OK")))))))) -> OK
A11: SMP-007 | B11: Search with a very long text | C11: Product Search | D11: Boundary | F11: Passed | H11: User is on the Luma home page. | I11: Search text: "aaaa aaaaa aaaaaaa aaaaaa aaaaaa" (a very long, made-up product name) | J11: 1. Click the search bar. 2. Type a very long text that matches no product (see Test Data). 3. Run the search. | K11: No products are shown, the message "Your search returned no results" is displayed, and the "Search results for:" heading fits on the page without breaking the layout. | Q11: When you click on the Search Bar that says "Search entire store here" And you type something with many characters And click "Enter" or click on the magnifying glass icon to search Then the website should display error message "Your search returned no results" And the "Search Results for:" should fit in the page without breaking its layout | R11: =IF(AND(A11="",B11=""),"",IF(A11="","Missing ID",IF(COUNTIF($A:$A,A11)>1,"Duplicate ID",IF(B11="","Missing title",IF(C11="","Missing module",IF(J11="","Missing steps",IF(K11="","Missing expected result",IF(AND(F11=St_Failed,L11=""),"Add actual result","OK")))))))) -> OK
A12: SMP-008 | B12: Search with only spaces | C12: Product Search | D12: Negative | F12: Passed | H12: User is on the Luma home page. | I12: Search text: blank spaces only | J12: 1. Click the search bar. 2. Type only blank spaces. 3. Press Enter or click the magnifying-glass icon. | K12: The website does not run a search. | Q12: When you click on the Search Bar that says "Search entire store here" And you type blank spaces And click "Enter" or click on the magnifying glass icon to search Then the website shouldn't search for anything | R12: =IF(AND(A12="",B12=""),"",IF(A12="","Missing ID",IF(COUNTIF($A:$A,A12)>1,"Duplicate ID",IF(B12="","Missing title",IF(C12="","Missing module",IF(J12="","Missing steps",IF(K12="","Missing expected result",IF(AND(F12=St_Failed,L12=""),"Add actual result","OK")))))))) -> OK
A13: SMP-009 | B13: Create an account with valid data | C13: Account Creation | D13: Functional | F13: Passed | H13: User is on the Luma home page. | I13: First name: Thomas Last name: Pessoa Email: tomecosabs@gmaill.com Password: Passw0rd123 | J13: 1. Click "Create an Account". 2. Fill in the required fields (see Test Data). 3. Click "Create an Account". | K13: The account is created, the user is logged in and is redirected to the "My Account" page, which shows the account information. | Q13: Given that you are at Luma's home page When you click on "Create an account" Then you should be redirected to a "Create New Customer Account" page When you type in your "First name" And then type in your "Last name" And fill in your sign in information, such as your "Email" And fill the "password" fields with matching passwords And click on "Create an Account" Then you should be logged in And be redirected to a "My Account" page where it contains all the info about your account | R13: =IF(AND(A13="",B13=""),"",IF(A13="","Missing ID",IF(COUNTIF($A:$A,A13)>1,"Duplicate ID",IF(B13="","Missing title",IF(C13="","Missing module",IF(J13="","Missing steps",IF(K13="","Missing expected result",IF(AND(F13=St_Failed,L13=""),"Add actual result","OK")))))))) -> OK
A14: SMP-010 | B14: Create an account with an email missing "@" | C14: Account Creation | D14: Negative | F14: Passed | H14: User is on the "Create New Customer Account" page. | I14: First name: Pedro Last name: Lennon Email: "pedropedrolennon" Password: Linkedin123 | J14: 1. Fill in the required fields. 2. In the Email field, type an invalid address without "@" (see Test Data). 3. Click "Create an Account". | K14: The account is not created and the message "Please enter a valid email address (Ex: johndoe@domain.com)." is displayed. | P14: The original run sheet used "abcde" as the invalid email. | Q14: Given that you are in the "Create New Customer Account" page When you type in your "First name" And then type in your "Last name" And fill in your sign in information with a fake "Email" And the "password" fields with matching passwords And click on "Create an Account" Then site should return an error message that says: "Please enter a valid email address (Ex: johndoe@domain.com)" | R14: =IF(AND(A14="",B14=""),"",IF(A14="","Missing ID",IF(COUNTIF($A:$A,A14)>1,"Duplicate ID",IF(B14="","Missing title",IF(C14="","Missing module",IF(J14="","Missing steps",IF(K14="","Missing expected result",IF(AND(F14=St_Failed,L14=""),"Add actual result","OK")))))))) -> OK
A15: SMP-011 | B15: Create an account with a numbers-only name | C15: Account Creation | D15: Negative | F15: Failed | H15: User is on the "Create New Customer Account" page. | I15: First name: 12345678 Last name: 87654321 Email: thomasemail@gmail.com Password: Brazil123 | J15: 1. Fill in the required fields. 2. Type only numbers in the First name and Last name fields (see Test Data). 3. Click "Create an Account". | K15: The account is not created and the website shows an error stating that the name fields cannot contain numbers. | L15: An account can be created with a name that contains only numbers. | P15: The original run sheet used "1234" as the name. | Q15: Given that you are in the "Create New Customer Account" page When you type in a "First name" that only contains numbers And type in a "Last name" that only contains numbers And fill in your sign in information with your "Email" And the "password" fields with matching passwords And click on "Create an Account" Then site should return an error message stating that the name fields cannot contain numbers | R15: =IF(AND(A15="",B15=""),"",IF(A15="","Missing ID",IF(COUNTIF($A:$A,A15)>1,"Duplicate ID",IF(B15="","Missing title",IF(C15="","Missing module",IF(J15="","Missing steps",IF(K15="","Missing expected result",IF(AND(F15=St_Failed,L15=""),"Add actual result","OK")))))))) -> OK
A16: SMP-012 | B16: Create an account with non-matching passwords | C16: Account Creation | D16: Negative | F16: Passed | H16: User is on the "Create New Customer Account" page. First name, Last name and Email are already filled in. | I16: Password: 123321!@##@! Confirm Password: 87687tp | J16: 1. Fill in the remaining required fields. 2. Type a value in the "Password" field. 3. Type a different value in the "Confirm Password" field. 4. Click "Create an Account". | K16: The account is not created and the message "Please enter same value again" is displayed. | Q16: Given that you are in the "Create New Customer Account" page And you have the previous fields filled. First name, Last name & Email When you fill in the "Password" field with a certain value And fill in the "Confirm password" with another/different value And click on "Create an Account" Then the website shouldn't allow your account to be created and should display a message that says "Please enter same value again" | R16: =IF(AND(A16="",B16=""),"",IF(A16="","Missing ID",IF(COUNTIF($A:$A,A16)>1,"Duplicate ID",IF(B16="","Missing title",IF(C16="","Missing module",IF(J16="","Missing steps",IF(K16="","Missing expected result",IF(AND(F16=St_Failed,L16=""),"Add actual result","OK")))))))) -> OK
A17: SMP-013 | B17: Create an account with a required field left empty | C17: Account Creation | D17: Negative | F17: Passed | H17: User is on the "Create New Customer Account" page. Only some fields are filled in (e.g. Last name and Email). | J17: 1. Leave one or more required fields (marked with "*") empty. 2. Click "Create an Account". | K17: The account is not created and "This is a required field." is displayed under each required field left empty. | Q17: Given that you are in the "Create New Customer Account" page And you have filled only a few fields of your desire. Ex: "Last name" & "Email" When you don't fill certain fields that contain a "*" besides their name. obs: A.k.a required field And click on "Create an Account" Then the website shouldn't let you create your account and should display a message that says "This is a required field." under the required fields that you didn't fill | R17: =IF(AND(A17="",B17=""),"",IF(A17="","Missing ID",IF(COUNTIF($A:$A,A17)>1,"Duplicate ID",IF(B17="","Missing title",IF(C17="","Missing module",IF(J17="","Missing steps",IF(K17="","Missing expected result",IF(AND(F17=St_Failed,L17=""),"Add actual result","OK")))))))) -> OK
A18: SMP-014 | B18: Create an account with a weak password | C18: Account Creation | D18: Negative | F18: Passed | H18: User is on the "Create New Customer Account" page. First name, Last name and Email are already filled in. | I18: Password: "abcdefghijklmnop" | J18: 1. Fill in the remaining required fields. 2. Type a weak password in the "Password" field (see Test Data). 3. Click "Create an Account". | K18: The password strength indicator shows "Weak" while typing, and the account is not created until a stronger password is used. | P18: The original run sheet used "123" as the weak password. | Q18: Given that you are in the "Create New Customer Account" page And you have the previous fields filled. First name, Last name & Email When you fill in the "Password" field with a weak password Then the website should display "Password strength: Weak" and it shouldn't allow you create your account until you make a strong password | R18: =IF(AND(A18="",B18=""),"",IF(A18="","Missing ID",IF(COUNTIF($A:$A,A18)>1,"Duplicate ID",IF(B18="","Missing title",IF(C18="","Missing module",IF(J18="","Missing steps",IF(K18="","Missing expected result",IF(AND(F18=St_Failed,L18=""),"Add actual result","OK")))))))) -> OK
A19: SMP-015 | B19: Create an account with a password shorter than 8 characters | C19: Account Creation | D19: Boundary | F19: Passed | H19: User is on the "Create New Customer Account" page. First name, Last name and Email are already filled in. | I19: Password: "abc" | J19: 1. Fill in the remaining required fields. 2. Type a password with fewer than 8 characters in the "Password" field (see Test Data). 3. Click "Create an Account". | K19: The account is not created and the message "Minimum length of this field must be equal or greater than 8 symbols. Leading and trailing spaces will be ignored." is displayed. | P19: The original run sheet used "000" as the password. | Q19: Given that you are in the "Create New Customer Account" page And you have the previous fields filled. First name, Last name & Email When you fill in the "Password" field with a password that contains less than 8 characters Then the website shouldn't allow you to create account And should display the following error message: "Minimum length of this field must be equal or greater than 8 symbols. Leading and trailing spaces will be ignored." | R19: =IF(AND(A19="",B19=""),"",IF(A19="","Missing ID",IF(COUNTIF($A:$A,A19)>1,"Duplicate ID",IF(B19="","Missing title",IF(C19="","Missing module",IF(J19="","Missing steps",IF(K19="","Missing expected result",IF(AND(F19=St_Failed,L19=""),"Add actual result","OK")))))))) -> OK
A20: SMP-016 | B20: Add one item to the cart | C20: Add to Cart | D20: Functional | F20: Failed | H20: User is on the Luma home page. | I20: Product: "Gobi HeatTec® Tee" Color: Orange Size: XL Quantity: 1 | J20: 1. Find the desired product and open it. 2. Select the size, color and quantity. 3. Click "Add to Cart". | K20: The item is added to the cart with the selected size, color and quantity. | L20: Item details and price are correct, but the image of the product color is incorrect, which can confuse the customer. | Q20: Given that you are at Luma's home page When you hover over an item you like Then you should be directed to the item's page When you select the desired Size & Color And click "Add to cart" Then item with desired Size and Color should be added to cart | R20: =IF(AND(A20="",B20=""),"",IF(A20="","Missing ID",IF(COUNTIF($A:$A,A20)>1,"Duplicate ID",IF(B20="","Missing title",IF(C20="","Missing module",IF(J20="","Missing steps",IF(K20="","Missing expected result",IF(AND(F20=St_Failed,L20=""),"Add actual result","OK")))))))) -> OK
A21: SMP-017 | B21: Add different items to the cart | C21: Add to Cart | D21: Functional | F21: Passed | H21: User is on the Luma home page or a category page (e.g. Jackets). | I21: Color: Blue Size: M Quantity: 2 (per item) | J21: 1. Open an item. 2. Select the size, color and quantity. 3. Click "Add to Cart". 4. Repeat with another item. | K21: All selected items are in the cart with their chosen size, color and quantity. | Q21: Given that you are at Luma's home page or at a category's page. Ex: "Jackets" When you click on an item you like When you select the desired Size & Color And fill in the desired Quantity that you want of the product And click on "Add to cart" And repeat this process to another item Then both of the selected items in their desired Color, Size and quantity should be in your cart | R21: =IF(AND(A21="",B21=""),"",IF(A21="","Missing ID",IF(COUNTIF($A:$A,A21)>1,"Duplicate ID",IF(B21="","Missing title",IF(C21="","Missing module",IF(J21="","Missing steps",IF(K21="","Missing expected result",IF(AND(F21=St_Failed,L21=""),"Add actual result","OK")))))))) -> OK
A22: SMP-018 | B22: Add 1000+ units of the same item | C22: Add to Cart | D22: Boundary | F22: Passed | H22: User is on the Luma home page or a category page (e.g. Tops). | I22: Color: Green Size: S Quantity: 1001 | J22: 1. Open an item. 2. Select the size and color. 3. Enter a quantity above 1000 (see Test Data). 4. Click "Add to Cart". | K22: The item is added to the cart with the large quantity and the correct size and color. | P22: The original test-case sheet listed 12345; the original run used 1001. The site's maximum quantity is 10000 (see SMP-028). | Q22: Given that you are at Luma's home page or at a category's page. Ex: "Tops" When you click on an item you like When you select the desired Size & Color And fill in the Quantity with a large number And click "Add to cart" Then item with large quantity should be added to cart, with its correct S&C | R22: =IF(AND(A22="",B22=""),"",IF(A22="","Missing ID",IF(COUNTIF($A:$A,A22)>1,"Duplicate ID",IF(B22="","Missing title",IF(C22="","Missing module",IF(J22="","Missing steps",IF(K22="","Missing expected result",IF(AND(F22=St_Failed,L22=""),"Add actual result","OK")))))))) -> OK
A23: SMP-019 | B23: Add a large number of different items to the cart | C23: Add to Cart | D23: Boundary | F23: Passed | H23: User is on the Luma home page or a category page (e.g. Tees). | I23: Color: Red Size: S Quantity: 3 (per item) Items: 50+ different items | J23: 1. Open an item. 2. Select the size, color and quantity. 3. Click "Add to Cart". 4. Repeat with 50+ other items. | K23: All items appear in the cart with their chosen size, color and quantity. | Q23: Given that you are at Luma's home page or at a category's page. Ex: "Tees" When you click on an item you like When you select the desired Size & Color And fill in the desired Quantity that you want of the product And click "Add to cart" And repeat this process to a lot of other items Then all items should appear in the cart with their correct Size and Color | R23: =IF(AND(A23="",B23=""),"",IF(A23="","Missing ID",IF(COUNTIF($A:$A,A23)>1,"Duplicate ID",IF(B23="","Missing title",IF(C23="","Missing module",IF(J23="","Missing steps",IF(K23="","Missing expected result",IF(AND(F23=St_Failed,L23=""),"Add actual result","OK")))))))) -> OK
A24: SMP-020 | B24: View item details in the mini cart | C24: Add to Cart | D24: Functional | F24: Passed | H24: At least one item is in the cart. User is on the Luma home page. | J24: 1. Click the cart icon next to the search bar. 2. Click "See Details" next to an item. | K24: A pop-up with the items in the cart appears, and the item details (size and color) are displayed. | Q24: Given that you have an item added to your cart And you are in the website's home page When you click on the Cart icon next to the search bar Then a pop up menu of the items in your cart should show When you click on "See details" of the desired item Then the details of that item should be displayed. Size & Color | R24: =IF(AND(A24="",B24=""),"",IF(A24="","Missing ID",IF(COUNTIF($A:$A,A24)>1,"Duplicate ID",IF(B24="","Missing title",IF(C24="","Missing module",IF(J24="","Missing steps",IF(K24="","Missing expected result",IF(AND(F24=St_Failed,L24=""),"Add actual result","OK")))))))) -> OK
A25: SMP-021 | B25: Edit item quantity in the mini cart | C25: Add to Cart | D25: Functional | F25: Passed | H25: One or more items are in the cart and the mini cart is open. | I25: Quantity change: from 20 to 9 | J25: 1. Click the quantity of the item to change. 2. Change the quantity. 3. Click "Update". | K25: The "Update" button appears after the quantity is changed, and the quantity and price of the item are updated. | Q25: Given that you have 1 or more items in your cart And you have the pop-up cart open When you click on the quantity of the item you want to alter And change the quantity Then "Update" button should appear When you click on "Update" Then quantity and PRICE of that certain item should be updated | R25: =IF(AND(A25="",B25=""),"",IF(A25="","Missing ID",IF(COUNTIF($A:$A,A25)>1,"Duplicate ID",IF(B25="","Missing title",IF(C25="","Missing module",IF(J25="","Missing steps",IF(K25="","Missing expected result",IF(AND(F25=St_Failed,L25=""),"Add actual result","OK")))))))) -> OK
A26: SMP-022 | B26: Edit an item from the mini cart | C26: Add to Cart | D26: Functional | F26: Passed | H26: One or more items are in the cart and the mini cart is open. | J26: 1. Click the pencil icon next to the item to edit. 2. On the product page, change the size and/or color. 3. Click "Update Cart". | K26: The user is taken to the item's page to edit it, and the cart shows the updated details. | Q26: Given that you have 1 or more items in your cart And you have the pop-up cart open When you click on the Pencil icon next to the item you want to edit Then you should be redirected to the page of the desired item where you can alter and update its information When you are done altering its Colors or Size And click in "Update Cart" Then item should be updated in your cart | R26: =IF(AND(A26="",B26=""),"",IF(A26="","Missing ID",IF(COUNTIF($A:$A,A26)>1,"Duplicate ID",IF(B26="","Missing title",IF(C26="","Missing module",IF(J26="","Missing steps",IF(K26="","Missing expected result",IF(AND(F26=St_Failed,L26=""),"Add actual result","OK")))))))) -> OK
A27: SMP-023 | B27: View all items on the cart page | C27: Add to Cart | D27: Functional | F27: Passed | H27: Items are in the cart. | J27: 1. Click the cart icon. 2. Click "View and Edit Cart". | K27: The Shopping Cart page opens, where all items can be viewed, edited and deleted. | Q27: Given that you have items added in your cart And you clicked in the cart icon And clicked on "View and edit cart" Then you should be redirected to your cart page. Where you can view, edit & delete all the items added to your cart | R27: =IF(AND(A27="",B27=""),"",IF(A27="","Missing ID",IF(COUNTIF($A:$A,A27)>1,"Duplicate ID",IF(B27="","Missing title",IF(C27="","Missing module",IF(J27="","Missing steps",IF(K27="","Missing expected result",IF(AND(F27=St_Failed,L27=""),"Add actual result","OK")))))))) -> OK
A28: SMP-024 | B28: Empty cart message on the Shopping Cart page | C28: Add to Cart | D28: Functional | F28: Passed | H28: Items are in the cart and the user is on the "Shopping Cart" page. | J28: 1. Delete all items from the cart. | K28: The message "You have no items in your shopping cart." is displayed and the page suggests continuing to shop. | Q28: Given that you are in the "Shopping Cart" page And you have items added to your cart When you delete the selected items Then the shopping cart page should show a message that says: "You have no items in your shopping cart." | R28: =IF(AND(A28="",B28=""),"",IF(A28="","Missing ID",IF(COUNTIF($A:$A,A28)>1,"Duplicate ID",IF(B28="","Missing title",IF(C28="","Missing module",IF(J28="","Missing steps",IF(K28="","Missing expected result",IF(AND(F28=St_Failed,L28=""),"Add actual result","OK")))))))) -> OK
A29: SMP-025 | B29: Empty cart message in the mini cart | C29: Add to Cart | D29: Functional | F29: Passed | H29: No items are in the cart. | J29: 1. Click the cart icon. | K29: The mini cart is empty and shows "You have no items in your shopping cart." | Q29: Given that you have no items added to your cart When you click on the Cart icon Then it should display a message saying: "You have no items in your shopping cart." | R29: =IF(AND(A29="",B29=""),"",IF(A29="","Missing ID",IF(COUNTIF($A:$A,A29)>1,"Duplicate ID",IF(B29="","Missing title",IF(C29="","Missing module",IF(J29="","Missing steps",IF(K29="","Missing expected result",IF(AND(F29=St_Failed,L29=""),"Add actual result","OK")))))))) -> OK
A30: SMP-026 | B30: Proceed to checkout from the cart | C30: Add to Cart | D30: Functional | F30: Passed | H30: One or more items are in the cart. | J30: 1. Open the cart (mini cart or Shopping Cart page). 2. Click "Proceed to Checkout". | K30: The "Proceed to Checkout" button is visible and the user is redirected to the Shipping page. | P30: The original test-case sheet used the Shopping Cart page; the original run sheet used the mini cart. | Q30: Given that you have added one or more items to your cart And you are in the Shopping cart page Then a "Proceed to checkout" button should be visible When clicked Then you should be redirected to the checkout page | R30: =IF(AND(A30="",B30=""),"",IF(A30="","Missing ID",IF(COUNTIF($A:$A,A30)>1,"Duplicate ID",IF(B30="","Missing title",IF(C30="","Missing module",IF(J30="","Missing steps",IF(K30="","Missing expected result",IF(AND(F30=St_Failed,L30=""),"Add actual result","OK")))))))) -> OK
A31: SMP-027 | B31: Add an item without selecting size and color | C31: Add to Cart | D31: Negative | F31: Passed | H31: User is viewing an item to add to the cart. | J31: 1. Do not select a size or a color. 2. Click "Add to Cart". | K31: The item is not added and the website informs the user that size and color are required. | Q31: Given that you are viewing an item you want to add to your cart When you click on "Add to your cart" without choosing a size or color Then the website should inform you that those fields are required | R31: =IF(AND(A31="",B31=""),"",IF(A31="","Missing ID",IF(COUNTIF($A:$A,A31)>1,"Duplicate ID",IF(B31="","Missing title",IF(C31="","Missing module",IF(J31="","Missing steps",IF(K31="","Missing expected result",IF(AND(F31=St_Failed,L31=""),"Add actual result","OK")))))))) -> OK
A32: SMP-028 | B32: Add an absurd quantity of the same item | C32: Add to Cart | D32: Boundary | F32: Passed | H32: User is on the Luma home page or a category page (e.g. Bags). | I32: Color: Pink Size: W Quantity: 9999999999999999999 | J32: 1. Open an item. 2. Select the size and color. 3. Enter a huge quantity (10000+; see Test Data). 4. Click "Add to Cart". | K32: The item is not added and the message "The maximum you may purchase is 10000." is displayed. | Q32: Given that you are at Luma's home page or at a category's page. Ex: "Bags" When you hover over an item you like And you select the desired Size & Color And fill in a crazy amount of the product that you want And click on "Add to cart" Then the website should display an error message that says: "The maximum you may purchase is 10000." | R32: =IF(AND(A32="",B32=""),"",IF(A32="","Missing ID",IF(COUNTIF($A:$A,A32)>1,"Duplicate ID",IF(B32="","Missing title",IF(C32="","Missing module",IF(J32="","Missing steps",IF(K32="","Missing expected result",IF(AND(F32=St_Failed,L32=""),"Add actual result","OK")))))))) -> OK
A33: SMP-029 | B33: Add a negative quantity | C33: Add to Cart | D33: Negative | F33: Passed | H33: User is on the Luma home page or a category page (e.g. Pants). | I33: Color: White Size: XW Quantity: -1 | J33: 1. Open an item. 2. Select the size and color. 3. Enter a negative quantity (see Test Data). 4. Click "Add to Cart". | K33: The item is not added and the message "Please enter a quantity greater than 0." is displayed. | Q33: Given that you are at Luma's home page or at a category's page. Ex: "Pants" When you hover over an item you like And you select the desired Size & Color And fill in a negative number on the quantity of the product that you want And click on "Add to cart" Then the website should display an error message that says: "Please enter a quantity greater than 0." | R33: =IF(AND(A33="",B33=""),"",IF(A33="","Missing ID",IF(COUNTIF($A:$A,A33)>1,"Duplicate ID",IF(B33="","Missing title",IF(C33="","Missing module",IF(J33="","Missing steps",IF(K33="","Missing expected result",IF(AND(F33=St_Failed,L33=""),"Add actual result","OK")))))))) -> OK
A34: SMP-030 | B34: Add an item with quantity zero | C34: Add to Cart | D34: Boundary | F34: Passed | H34: User is on the Luma home page or a category page (e.g. Pants). | I34: Color: Purple Size: M Quantity: 0 | J34: 1. Open an item. 2. Select the size and color. 3. Enter 0 as the quantity. 4. Click "Add to Cart". | K34: The item is not added and the message "Please enter a quantity greater than 0." is displayed. | Q34: Given that you are at Luma's home page or at a category's page. Ex: "Pants" When you hover over an item you like And you select the desired Size & Color And fill in a zero on the quantity of the product that you want And click on "Add to cart" Then the website should display an error message that says: "Please enter a quantity greater than 0." | R34: =IF(AND(A34="",B34=""),"",IF(A34="","Missing ID",IF(COUNTIF($A:$A,A34)>1,"Duplicate ID",IF(B34="","Missing title",IF(C34="","Missing module",IF(J34="","Missing steps",IF(K34="","Missing expected result",IF(AND(F34=St_Failed,L34=""),"Add actual result","OK")))))))) -> OK
A35: SMP-031 | B35: Add a product to the cart from search results | C35: Add to Cart | D35: Functional | F35: Passed | H35: User has searched for a product to purchase. | I35: Product: "Radiant Tee" Color: Orange Size: S Quantity: 33 | J35: 1. Search for the desired product and open it. 2. Select the size, color and quantity. 3. Click "Add to Cart". | K35: The item is added to the cart with the selected size, color and quantity. | Q35: Given that I have searched for a product that I want to purchase When you hover over an item you like And you select the desired Size & Color And fill in the desired Quantity that you want of the product And click "Add to cart" Then item with desired Size and Color should be added to cart | R35: =IF(AND(A35="",B35=""),"",IF(A35="","Missing ID",IF(COUNTIF($A:$A,A35)>1,"Duplicate ID",IF(B35="","Missing title",IF(C35="","Missing module",IF(J35="","Missing steps",IF(K35="","Missing expected result",IF(AND(F35=St_Failed,L35=""),"Add actual result","OK")))))))) -> OK
A36: SMP-032 | B36: Add a product to the cart from a category page | C36: Add to Cart | D36: Functional | F36: Passed | H36: User is on a category page. | I36: Category: Mens > Bottom > Pants Color: Yellow Size: XS Quantity: 11 | J36: 1. Open an item from the category page. 2. Select the size, color and quantity. 3. Click "Add to Cart". | K36: The item is added to the cart with the selected size, color and quantity. | Q36: Given that I'm in a certain category When you hover over an item you like And you select the desired Size & Color And fill in the desired Quantity that you want of the product And click "Add to cart" Then item with desired Size and Color should be added to cart | R36: =IF(AND(A36="",B36=""),"",IF(A36="","Missing ID",IF(COUNTIF($A:$A,A36)>1,"Duplicate ID",IF(B36="","Missing title",IF(C36="","Missing module",IF(J36="","Missing steps",IF(K36="","Missing expected result",IF(AND(F36=St_Failed,L36=""),"Add actual result","OK")))))))) -> OK
A37: SMP-033 | B37: Buy a product for the first time | C37: Ordering | D37: Functional | F37: Passed | H37: It is the user's first purchase and an item is in the cart. | I37: Product: "Tiberius Gym Tank" Street Address: 1540 S 8th St City: Colorado Springs State: Colorado ZIP: 80937 Phone: 561-562-0019 | J37: 1. Click "Proceed to Checkout". 2. On the Shipping page, check that First name and Last name are pre-filled. 3. Fill in the required shipping fields (see Test Data). 4. Select a shipping method and click "Next". 5. On the Review & Payments page, check the order information (items, price, shipping address, shipping method). 6. Click "Place Order". | K37: The order is placed. A "Thank you for your purchase!" message and the order ID are displayed. | Q37: Given that is your first time buying an item And that you have an item in your cart When you click on "Proceed to checkout" Then you should be redirected to a Shipping page And the "First name" & "Last name" should be already filled in When you fill in the required fields such as Street Address: And the City And select a State or Province And fill in a Zip/Postal code And fill in your Phone number When you select a shipping method And click on Next Then you should be taken to a Review & payments page And your Order and its information should be there, such as Price And Item in cart, with its details And The shipping address And the shipping methods When you click on "Place your order" Then your order should be done And the website will display a "Thank you for your purchase!" message along with your order's ID | R37: =IF(AND(A37="",B37=""),"",IF(A37="","Missing ID",IF(COUNTIF($A:$A,A37)>1,"Duplicate ID",IF(B37="","Missing title",IF(C37="","Missing module",IF(J37="","Missing steps",IF(K37="","Missing expected result",IF(AND(F37=St_Failed,L37=""),"Add actual result","OK")))))))) -> OK
A38: SMP-034 | B38: Buy a product as a returning customer | C38: Ordering | D38: Functional | F38: Passed | H38: User has purchased before and an item is in the cart. | I38: Product: "Circe Hooded Ice Fleece" Color: Grey Size: S | J38: 1. Click "Proceed to Checkout". 2. On the Shipping page, check that the address from the previous order is selected. 3. Select a shipping method and click "Next". 4. On the Payment & Review page, click "Place Order". | K38: The address from the previous order is pre-selected. The order is placed and a "Thank you for your purchase!" message with the order ID is displayed. | Q38: Given that you have purchased before And you had an item in your cart And you proceeded to the checkout Then you should be redirected to the Shipping page And your address from the previous order should be selected When you select your shipping method And click on Next Then you should be taken to the Payment & Review page When you click on "Place order" Then your order should be completed And the website will display a "Thank you for your purchase!" message along with your order's ID | R38: =IF(AND(A38="",B38=""),"",IF(A38="","Missing ID",IF(COUNTIF($A:$A,A38)>1,"Duplicate ID",IF(B38="","Missing title",IF(C38="","Missing module",IF(J38="","Missing steps",IF(K38="","Missing expected result",IF(AND(F38=St_Failed,L38=""),"Add actual result","OK")))))))) -> OK
A39: SMP-035 | B39: Continue shopping after placing an order | C39: Ordering | D39: Functional | F39: Passed | H39: User has placed an order and is on the "Thank you for your purchase" page. | J39: 1. Click "Continue Shopping". | K39: The user is taken to the home page and can continue shopping. | Q39: Given that you've placed an order And you are in the "Thank you for your purchase" page When you click on "Continue shopping" Then you should be taken to the home page to continue shopping | R39: =IF(AND(A39="",B39=""),"",IF(A39="","Missing ID",IF(COUNTIF($A:$A,A39)>1,"Duplicate ID",IF(B39="","Missing title",IF(C39="","Missing module",IF(J39="","Missing steps",IF(K39="","Missing expected result",IF(AND(F39=St_Failed,L39=""),"Add actual result","OK")))))))) -> OK
A40: SMP-036 | B40: View orders while logged in | C40: Ordering | D40: Functional | F40: Passed | H40: User has already placed an order, is logged in and is on the home page. | J40: 1. Click the user name in the top-right corner and select "My Account". 2. Click "My Orders". | K40: The user can see their previous orders and their information. | Q40: Given that you have already placed an order And you are logged in And you are in the home page When you click on your name in the top right corner of the website And click on "My account" Then you should be redirected to a "My account" page When you click on "My orders" Then you should be able to view your orders | R40: =IF(AND(A40="",B40=""),"",IF(A40="","Missing ID",IF(COUNTIF($A:$A,A40)>1,"Duplicate ID",IF(B40="","Missing title",IF(C40="","Missing module",IF(J40="","Missing steps",IF(K40="","Missing expected result",IF(AND(F40=St_Failed,L40=""),"Add actual result","OK")))))))) -> OK
...

Sheet Lists
A1: Lists
A2: These lists feed the dropdowns on Test Cases and the labels on the Dashboard. Type a new value in an empty blue cell to add it; overwrite a value to rename it.
A3: Keep the five Status values in order (the Dashboard counts them by position). Severity rows 1 and 2 drive the red and orange highlighting.
A4: Status | B4: Meaning | D4: Priority | F4: Severity | H4: Test Type | J4: Environment | L4: Feature / Module | N4: ID Prefix
A5: Not Run | B5: Not executed yet. | D5: Critical | F5: Critical | H5: Functional | J5: Local | L5: Cross-Browser Compatibility | N5: TC
A6: Passed | B6: Actual result matched the expected result. | D6: High | F6: High | H6: Regression | J6: Dev | L6: Product Search | N6: New IDs look like TC-001
A7: Failed | B7: Actual result differs from the expected result (a defect). | D7: Medium | F7: Medium | H7: Smoke | J7: QA | L7: Account Creation
A8: Blocked | B8: Could not run because of an outside problem (environment down, blocking defect, missing data). | D8: Low | F8: Low | H8: Exploratory | J8: Staging | L8: Add to Cart
A9: Skipped | B9: Intentionally not run in this cycle. | H9: UI | J9: UAT | L9: Ordering
H10: API | J10: Production
H11: Integration | J11: Chrome
H12: Negative | J12: Firefox
H13: Boundary | J13: Safari
H14: Compatibility | J14: Edge
H15: Other

Sheet Sample Project
B1: Sample Project
B2: Background for the sample test cases.
B4: Project | C4: Private QA project on a public demo store, used to practice and showcase manual testing.
B5: Scope | C5: 1. Create test cases based on the requirements. 2. Deliver a test run report where passes and failures can be reviewed. 3. Find bugs on the website and report them in a bug tracking system.
B6: Application under test | C6: https://magento.softwaretestingboard.com/
B7: Bug tracking | C7: A Trello board with a bug tracking system and bug reports for defects found on the website.
B8: Bug board link | C8: Bug tracking board and bug reports (Trello)
